Workbook
Name Slicer_Año: #N/A
Name Slicer_canal_pago: #N/A
Name Slicer_categoria1: #N/A
Name Slicer_categoria2: #N/A
Name Slicer_centro_coste: #N/A
Name Slicer_empresa: #N/A
Name Slicer_pais: #N/A
Name Slicer_pais1: #N/A

Sheet Resumen Ejecutivo
C1: OPTIMIZACIÓN FINANCIERA 2024-2026

Sheet Estado Transacciones
C1: ESTADOS
C3: ='_Estado'!B6 -> 7278844.7 | F3: ='_Estado'!B9 -> 1117332.4 | I3: ='_Estado'!B12 -> 944452.67 | L3: ='_Estado'!B15 -> 366779.19
C5: Importe Pagado | F5: Importe Pendiente | I5: Importe Cancelado | L5: Importe Rechazado
C8: ='_Estado'!B18 -> Revisar
C9: Alerta Pendiente

Sheet Rentabilidad
C1: RENTABILIDAD
C3: ='_Rentabilidad'!B6 -> -311657.8 | F3: ='_Rentabilidad'!B9 -> -0.066340156 | I3: ='_Rentabilidad'!B12 -> 0.20055751
C5: Saldo Neto | F5: Margen Neto % | I5: Crecimiento Ingresos YoY %
C8: ='_Rentabilidad'!B15 -> Revisar
C9: Alerta Rentavividad

Sheet Gastos y Control
C1: GASTOS Y CONTROL GASTOS Y CONTROL GASTOS Y CONTROL
C3: ='_Gasto y Control'!B6 -> 5009533.4 | F3: ='_Gasto y Control'!B9 -> 417461.12 | I3: ='_Gasto y Control'!B12 -> Comercial
C5: Total Gastos | F5: Gasto Promedio Mensual | I5: Centro Coste Más Alto
C8: ='_Gasto y Control'!B15 -> Normal
C9: Alerta Sobrecoste

Sheet Clientes - Proveedores
C1: CLIENTES / PROVEEDORES
C3: ='_Cliente-Proveedor'!B6 -> 4697875.6 | F3: ='_Cliente-Proveedor'!B9 -> 5009533.4 | I3: ='_Cliente-Proveedor'!B12 -> 980
C5: Importe Cliente | F5: Importe Proveedor | I5: Clientes Activos
C8: ='_Cliente-Proveedor'!B15 -> 0.458279 | N8: ='_Cliente-Proveedor'!B18 -> 0.42435369
C9: Top 5 Clientes | N9: Top 5 Proveedores

Sheet Graficas
B2: Resumen Ejecutivo | H2: Estados | V2: Rentavilidad | AH2: Gastos y Control GASTOS Y CONTROL Gastos y Control | AW2: Clientes - Proveedores
B4: Row Labels | C4: Saldo Neto | E4: Total Ingresos | F4: Total Gastos | H4: Row Labels | I4: Sum of importe_limpio | K4: Row Labels | L4: Transacciones | N4: Row Labels | O4: Importe Pendiente | P4: Importe Cancelado | Q4: Importe Rechazado | S4: Row Labels | T4: Importe Pendiente | V4: Row Labels | W4: Total Ingresos | AB4: Row Labels | AC4: Margen Neto % | AE4: Row Labels | AF4: Total Gastos | AH4: Row Labels | AI4: Importe Categoria | AK4: Row Labels | AL4: Participación Categoria x Total | AN4: Row Labels | AO4: Total Gastos | AQ4: Row Labels | AR4: Var Gasto MoM | AT4: Row Labels | AU4: Var Gasto MoM % | AW4: Row Labels | AX4: Importe Cliente | AZ4: Row Labels | BA4: Importe Proveedor
B5: 2024 | E5: 4697875.6 | F5: 5009533.4 | H5: Rechazado | I5: 366779.19 | K5: Pagado | L5: 701 | N5: Comercial | O5: 97240.93 | P5: 107817.2 | Q5: 25446.25 | S5: Julia Roldán Calvet S.A. | T5: 7278.08 | V5: Nómina | W5: 154787.59 | AB5: 2024 | AE5: 2024 | AH5: Ventas | AI5: 147979 | AK5: Ventas | AL5: 0.031499131 | AN5: 2024 | AQ5: 2024 | AT5: 2024 | AW5: Comercializadora LE S.Com. | AX5: 120822 | AZ5: Comercial Salamanca S.A. | BA5: 174173
B6: 1 | C6: 39872.04 | H6: Cancelado | I6: 944452.67 | K6: Pendiente | L6: 161 | N6: Dirección | O6: 676914.76 | P6: 47014.72 | Q6: 64767.33 | S6: Bernardo Villena Casanova S.L. | T6: 8893.42 | V6: Servicios | W6: 173085.85 | AB6: 1 | AC6: 0.5446718 | AE6: 1 | AF6: 125735.07 | AH6: Servicios | AI6: 151630.46 | AK6: Servicios | AL6: 0.032276389 | AN6: 1 | AO6: 33331.75 | AQ6: 1 | AR6: 33331.75 | AT6: 1 | AU6: 0 | AW6: Logística HPBU S.Com. | AX6: 123458 | AZ6: Blanco y asociados S.Coop. | BA6: 199899
B7: 2 | C7: -10999.12 | E7: Total Ingresos | F7: Total Gastos | H7: Pendiente | I7: 1117332.4 | K7: Cancelado | L7: 70 | N7: Finanzas | O7: 74552.25 | P7: 478471.03 | Q7: 201300.25 | S7: Che Alarcón Somoza S.A. | T7: 9304.04 | V7: Otros | W7: 315146.66 | AB7: 2 | AC7: -0.23744778 | AE7: 2 | AF7: 214486.02 | AH7: Marketing | AI7: 157022.3 | AK7: Marketing | AL7: 0.033424108 | AN7: 2 | AO7: 57321.39 | AQ7: 2 | AR7: 23989.64 | AT7: 2 | AU7: 0.71972339 | AW7: Blazquez & Asociados S.Coop. | AX7: 139804 | AZ7: Soluciones Castellana S.Coop. | BA7: 248092
B8: 3 | C8: 40227.76 | E8: =VALUE(E5) -> 4697875.6 | F8: =VALUE(F5) -> 5009533.4 | H8: Pagado | I8: 7278844.7 | K8: Rechazado | L8: 70 | N8: Operaciones | O8: 95479.62 | P8: 25852.68 | Q8: 22932.83 | S8: Zabala y asociados S.L.L. | T8: 9409.95 | V8: Consultoría | W8: 346977.05 | AB8: 3 | AC8: 0.53416446 | AE8: 3 | AF8: 1065581.7 | AH8: Nómina | AI8: 182848.3 | AK8: Nómina | AL8: 0.038921486 | AN8: 3 | AO8: 35081.93 | AQ8: 3 | AR8: -22239.46 | AT8: 3 | AU8: -0.38797838 | AW8: Claudio Ángel Oller S.L. | AX8: 198305 | AZ8: Abilio Roldán Azorin S.L.L. | BA8: 258294
B9: 4 | C9: -7608.91 | H9: Grand Total | I9: 9707409 | K9: Grand Total | L9: 1002 | N9: RRHH | O9: 68734.31 | P9: 48348.39 | Q9: 26157.65 | S9: Desarrollo LX S.L. | T9: 575180 | V9: Ventas | W9: 355615.28 | AB9: 4 | AC9: -0.11121741 | AE9: 4 | AF9: 644975.25 | AH9: Consultoría | AI9: 487446.16 | AK9: Consultoría | AL9: 0.10375885 | AN9: 4 | AO9: 76023.65 | AQ9: 4 | AR9: 40941.72 | AT9: 4 | AU9: 1.1670316 | AW9: Paula Sans Botella S.L. | AX9: 246112.61 | AZ9: Servicios Salmerón S.L. | BA9: 266083
B10: 5 | C10: 671594.96 | N10: TI | O10: 104410.53 | P10: 236948.65 | Q10: 26174.88 | S10: Grand Total | T10: 610065.49 | V10: Impuestos | W10: 448899.04 | AB10: 5 | AC10: 0.86966088 | AE10: 2025 | AH10: Logística | AI10: 521517.74 | AK10: Logística | AL10: 0.1110114 | AN10: 5 | AO10: 100654.29 | AQ10: 5 | AR10: 24630.64 | AT10: 5 | AU10: 0.32398655 | AW10: Compañía Lloret & Asociados S.A. | AX10: 278200 | AZ10: Comercializadora Globales S.Com. | BA10: 292104.99
B11: 6 | C11: 28974.69 | N11: Grand Total | O11: 1117332.4 | P11: 944452.67 | Q11: 366779.19 | V11: Financiación | W11: 500633.11 | AB11: 6 | AC11: 0.43386475 | AE11: 1 | AF11: 569671.26 | AH11: Impuestos | AI11: 647656.33 | AK11: Impuestos | AL11: 0.13786153 | AN11: 6 | AO11: 37808.08 | AQ11: 6 | AR11: -62846.21 | AT11: 6 | AU11: -0.62437686 | AW11: DESCONOCIDO | AX11: 372074.74 | AZ11: Restauración Gracia S.Com. | BA11: 342702
B12: 7 | C12: -902467.6 | H12: Row Labels | I12: Transacciones | V12: Marketing | W12: 615944.27 | AB12: 7 | AC12: -18.933211 | AE12: 2 | AF12: 215048.22 | AH12: Financiación | AI12: 726246.89 | AK12: Financiación | AL12: 0.15459049 | AN12: 7 | AO12: 950133.45 | AQ12: 7 | AR12: 912325.37 | AT12: 7 | AU12: 24.130434 | AW12: Enrique Ripoll Pujol S.A. | AX12: 401737 | AZ12: Transportes Ibérica S.Coop. | BA12: 377182
B13: 8 | C13: -3576.79 | H13: Cancelado | I13: 70 | N13: Row Labels | O13: Importe Pendiente | P13: Importe Cancelado | Q13: Importe Rechazado | S13: Row Labels | T13: Importe Cancelado | V13: Suministros | W13: 854355.55 | AB13: 8 | AC13: -0.063071092 | AE13: 3 | AF13: 446088.07 | AH13: Otros | AI13: 932368.48 | AK13: Otros | AL13: 0.19846598 | AN13: 8 | AO13: 60287.24 | AQ13: 8 | AR13: -889846.21 | AT13: 8 | AU13: -0.93654866 | AW13: Hermanos Seco S.L. | AX13: 441987 | AZ13: Maza y Valenciano S.L.U. | BA13: 538645
B14: 9 | C14: 14138.07 | H14: Rechazado | I14: 70 | N14: Bizum | O14: 666371.09 | P14: 36553.88 | Q14: 180902.38 | S14: Infraestructuras BD S.L.N.E | T14: 8098.95 | V14: Logística | W14: 932431.2 | AB14: 9 | AC14: 0.20401523 | AE14: 4 | AF14: 457824.2 | AH14: Suministros | AI14: 1054817.7 | AK14: Suministros | AL14: 0.22453079 | AN14: 9 | AO14: 55161.02 | AQ14: 9 | AR14: -5126.22 | AT14: 9 | AU14: -0.085029933 | AW14: Chaparro & Asociados S.C.P | AX14: 658939 | AZ14: Desarrollo LX S.L. | BA14: 575180
B15: 10 | C15: 326101.79 | H15: Pendiente | I15: 161 | N15: Efectivo | O15: 73744.47 | P15: 247895.03 | Q15: 38340.94 | S15: Distribuciones Coca S.A. | T15: 9461.59 | V15: Grand Total | W15: 4697875.6 | AB15: 10 | AC15: 0.85163889 | AE15: 2026 | AH15: Grand Total | AI15: 5009533.4 | AK15: Grand Total | AL15: 1.0663402 | AN15: 10 | AO15: 56809.08 | AQ15: 10 | AR15: 1648.06 | AT15: 10 | AU15: 0.029877258 | AW15: Grand Total | AX15: 2981439.4 | AZ15: Grand Total | BA15: 3272355
B16: 11 | C16: 123474.08 | H16: Pagado | I16: 701 | N16: Paypal | O16: 95116.6 | P16: 116368.49 | Q16: 25919.26 | S16: Manufacturas del Noroeste S.L.N.E | T16: 78034 | AB16: 11 | AC16: 0.67007811 | AE16: 1 | AF16: 1210028.2 | AN16: 11 | AO16: 60794.11 | AQ16: 11 | AR16: 3985.03 | AT16: 11 | AU16: 0.070147765
B17: 12 | C17: -481903.78 | H17: Grand Total | I17: 1002 | N17: SEPA | O17: 85071.29 | P17: 35916.82 | Q17: 45715.55 | S17: Blanco y asociados S.Coop. | T17: 199899 | AB17: 12 | AC17: -10.598681 | AE17: 2 | AF17: 60095.35 | AN17: 12 | AO17: 527372.06 | AQ17: 12 | AR17: 466577.95 | AT17: 12 | AU17: 7.6747229
B18: 2025 | N18: Tarjeta | O18: 102107.85 | P18: 22767.81 | Q18: 35314.09 | S18: Hermanos Seco S.L. | T18: 441987 | V18: Row Labels | W18: Margen Neto x Categoria | Y18: Row Labels | Z18: Margen Neto % | AB18: 2025 | AE18: Grand Total | AF18: 5009533.4 | AH18: Row Labels | AI18: Importe Centro Coste | AK18: Row Labels | AL18: Participación Centro Coste x Total | AN18: 2025 | AQ18: 2025 | AT18: 2025 | AW18: Row Labels | AX18: Participación Cli x Total | AZ18: Row Labels | BA18: Participación Pro x Total
B19: 1 | C19: 232116.87 | H19: Row Labels | I19: Importe Pagado | J19: Importe Pendiente | K19: Importe Cancelado | L19: Importe Rechazado | N19: Transferencia | O19: 94921.1 | P19: 484950.64 | Q19: 40586.97 | S19: Grand Total | T19: 737480.54 | V19: Otros | W19: -617221.82 | Y19: Otros | Z19: -1.9585225 | AB19: 1 | AC19: 0.79576296 | AH19: Comercial | AI19: 457124.51 | AK19: Comercial | AL19: 0.091250916 | AN19: 1 | AO19: 59574.1 | AQ19: 1 | AR19: -467797.96 | AT19: 1 | AU19: -0.88703592 | AW19: Comercializadora LE S.Com. | AX19: 0.025718433 | AZ19: Comercial Salamanca S.A. | BA19: 0.034768308
B20: 2 | C20: -399838.17 | H20: Andes Investments SL | I20: 2096015.5 | J20: 654969.07 | K20: 473666.69 | L20: 144035.46 | N20: Grand Total | O20: 1117332.4 | P20: 944452.67 | Q20: 366779.19 | V20: Financiación | W20: -225613.78 | Y20: Financiación | Z20: -0.45065693 | AB20: 2 | AC20: -8.4414916 | AH20: RRHH | AI20: 617708.03 | AK20: RRHH | AL20: 0.1233065 | AN20: 2 | AO20: 447203.99 | AQ20: 2 | AR20: 387629.89 | AT20: 2 | AU20: 6.5066848 | AW20: Logística HPBU S.Com. | AX20: 0.026279538 | AZ20: Blanco y asociados S.Coop. | BA20: 0.039903716
B21: 3 | C21: 432580.57 | H21: Atlantic Holdings SL | I21: 1099120.1 | J21: 124094.72 | K21: 24902.51 | L21: 53711.2 | V21: Suministros | W21: -200462.19 | Y21: Impuestos | Z21: -0.44276613 | AB21: 3 | AC21: 0.87306457 | AE21: Row Labels | AF21: Total Ingresos | AH21: Finanzas | AI21: 820113.76 | AK21: Finanzas | AL21: 0.16371061 | AN21: 3 | AO21: 62893.17 | AQ21: 3 | AR21: -384310.82 | AT21: 3 | AU21: -0.85936358 | AW21: Blazquez & Asociados S.Coop. | AX21: 0.029758983 | AZ21: Soluciones Castellana S.Coop. | BA21: 0.049523974
B22: 4 | C22: -7903.17 | H22: Cresta Partners SA | I22: 1265637.4 | J22: 80234.09 | K22: 35157.37 | L22: 34281.66 | N22: Row Labels | O22: Importe Pendiente | P22: Importe Cancelado | Q22: Importe Rechazado | S22: Row Labels | T22: Importe Rechazado | V22: Impuestos | W22: -198757.29 | Y22: Consultoría | Z22: -0.40483689 | AB22: 4 | AC22: -0.13223143 | AE22: 2024 | AH22: Operaciones | AI22: 846229.94 | AK22: Operaciones | AL22: 0.1689239 | AN22: 4 | AO22: 67670.88 | AQ22: 4 | AR22: 4777.71 | AT22: 4 | AU22: 0.075965482 | AW22: Claudio Ángel Oller S.L. | AX22: 0.042211633 | AZ22: Abilio Roldán Azorin S.L.L. | BA22: 0.051560491
B23: 5 | C23: -14065.17 | H23: Grupo Meridian SA | I23: 830684.92 | J23: 82181.6 | K23: 251930.87 | L23: 32265.27 | N23: Alemania | O23: 32743.76 | P23: 11404.2 | Q23: 13213.6 | S23: Supermercados Globales S.Coop. | T23: 6444.58 | V23: Consultoría | W23: -140469.11 | Y23: Suministros | Z23: -0.23463556 | AB23: 5 | AC23: -0.20515266 | AE23: 1 | AF23: 194835.75 | AH23: TI | AI23: 1130009.2 | AK23: TI | AL23: 0.22557175 | AN23: 5 | AO23: 82624.7 | AQ23: 5 | AR23: 14953.82 | AT23: 5 | AU23: 0.22097865 | AW23: Paula Sans Botella S.L. | AX23: 0.052388065 | AZ23: Servicios Salmerón S.L. | BA23: 0.053115326
B24: 6 | C24: -15957.22 | H24: Iberia Finance SL | I24: 1091621.2 | J24: 59782.94 | K24: 107694.53 | L24: 42162.82 | N24: España | O24: 949321.72 | P24: 871826.28 | Q24: 146883.72 | S24: Hnos Casas S.L. | T24: 6708.54 | V24: Nómina | W24: -28060.71 | Y24: Nómina | Z24: -0.18128527 | AB24: 6 | AC24: -0.32702291 | AE24: 2 | AF24: 907446.76 | AH24: Dirección | AI24: 1138347.9 | AK24: Dirección | AL24: 0.22723632 | AN24: 6 | AO24: 64752.64 | AQ24: 6 | AR24: -17872.06 | AT24: 6 | AU24: -0.21630408 | AW24: Compañía Lloret & Asociados S.A. | AX24: 0.059218256 | AZ24: Comercializadora Globales S.Com. | BA24: 0.05830982
B25: 7 | C25: -35744.19 | H25: Nordic Capital SA | I25: 895765.64 | J25: 116069.98 | K25: 51100.7 | L25: 60322.78 | N25: Francia | O25: 44802.11 | P25: 10856.47 | Q25: 39326.18 | S25: Familia Prat S.A. | T25: 8129.98 | V25: Servicios | W25: 21455.39 | Y25: Servicios | Z25: 0.12395808 | AB25: 7 | AC25: -1.6896811 | AE25: 3 | AF25: 173675.39 | AH25: Grand Total | AI25: 5009533.4 | AK25: Grand Total | AL25: 1 | AN25: 7 | AO25: 56898.59 | AQ25: 7 | AR25: -7854.05 | AT25: 7 | AU25: -0.12129312 | AW25: DESCONOCIDO | AX25: 0.079200637 | AZ25: Restauración Gracia S.Com. | BA25: 0.068409964
B26: 8 | C26: 430158.63 | H26: Grand Total | I26: 7278844.7 | J26: 1117332.4 | K26: 944452.67 | L26: 366779.19 | N26: Italia | O26: 30653.79 | P26: 20601.82 | Q26: 124781.37 | S26: Hnos Luís S.A. | T26: 9190 | V26: Ventas | W26: 207636.28 | Y26: Logística | Z26: 0.44069038 | AB26: 8 | AC26: 0.57607326 | AE26: 4 | AF26: 612647.34 | AN26: 8 | AO26: 316549.58 | AQ26: 8 | AR26: 259650.99 | AT26: 8 | AU26: 4.5633994 | AW26: Enrique Ripoll Pujol S.A. | AX26: 0.08551461 | AZ26: Transportes Ibérica S.Coop. | BA26: 0.075292841
B27: 9 | C27: -28490.62 | N27: Portugal | O27: 59811.02 | P27: 29763.9 | Q27: 42574.32 | S27: Comercializadora LE S.Com. | T27: 120822 | V27: Logística | W27: 410913.46 | Y27: Ventas | Z27: 0.58387896 | AB27: 9 | AC27: -0.64532468 | AE27: 2025 | AN27: 9 | AO27: 72639.9 | AQ27: 9 | AR27: -243909.68 | AT27: 9 | AU27: -0.77052599 | AW27: Hermanos Seco S.L. | AX27: 0.094082312 | AZ27: Maza y Valenciano S.L.U. | BA27: 0.10752399
B28: 10 | C28: -284593.99 | H28: Row Labels | I28: Importe Pendiente | N28: Grand Total | O28: 1117332.4 | P28: 944452.67 | Q28: 366779.19 | S28: Grand Total | T28: 151295.1 | V28: Marketing | W28: 458921.97 | Y28: Marketing | Z28: 0.74507061 | AB28: 10 | AC28: -4.6784537 | AE28: 1 | AF28: 834530.53 | AN28: 10 | AO28: 345424.77 | AQ28: 10 | AR28: 272784.87 | AT28: 10 | AU28: 3.7553035 | AW28: Chaparro & Asociados S.C.P | AX28: 0.14026319 | AZ28: Desarrollo LX S.L. | BA28: 0.11481708
B29: 11 | C29: 5569.58 | H29: Iberia Finance SL | I29: 59782.94 | V29: Grand Total | W29: -311657.8 | Y29: Grand Total | Z29: -0.066340156 | AB29: 11 | AC29: 0.084713672 | AE29: 2 | AF29: 177122.66 | AN29: 11 | AO29: 60176.36 | AQ29: 11 | AR29: -285248.41 | AT29: 11 | AU29: -0.82579026 | AW29: Grand Total | AX29: 0.63463565 | AZ29: Grand Total | BA29: 0.65322551
B30: 12 | C30: 22008.23 | H30: Cresta Partners SA | I30: 80234.09 | AB30: 12 | AC30: 0.29648181 | AE30: 3 | AF30: 812011.89 | AN30: 12 | AO30: 52223.07 | AQ30: 12 | AR30: -7953.29 | AT30: 12 | AU30: -0.13216635
B31: 2026 | H31: Grupo Meridian SA | I31: 82181.6 | N31: Row Labels | O31: Importe Pendiente | AB31: 2026 | AE31: 4 | AF31: 200808.02 | AN31: 2026 | AQ31: 2026 | AT31: 2026
B32: 1 | C32: 13532.09 | H32: Nordic Capital SA | I32: 116069.98 | N32: enero | O32: 40734.54 | S32: enero | T32: =VALUE(O32) -> 40734.54 | AB32: 1 | AC32: 0.18389367 | AE32: 2026 | AN32: 1 | AO32: 60054.4 | AQ32: 1 | AR32: 7831.33 | AT32: 1 | AU32: 0.1499592
B33: 2 | C33: -461736.51 | H33: Atlantic Holdings SL | I33: 124094.72 | N33: febrero | O33: 75594.46 | S33: febrero | T33: =VALUE(O33) -> 75594.46 | AB33: 2 | AC33: -8.2906 | AE33: 1 | AF33: 171765.99 | AN33: 2 | AO33: 517430.49 | AQ33: 2 | AR33: 457376.09 | AT33: 2 | AU33: 7.6160296
B34: 3 | C34: -590057.84 | H34: Andes Investments SL | I34: 654969.07 | N34: marzo | O34: 617081.34 | S34: marzo | T34: =VALUE(O34) -> 617081.34 | AB34: 3 | AC34: -13.888446 | AE34: 2 | AF34: 613031.27 | AN34: 3 | AO34: 632543.36 | AQ34: 3 | AR34: 115112.87 | AT34: 3 | AU34: 0.22247021
B35: 4 | C35: 552935.92 | H35: Grand Total | I35: 1117332.4 | N35: abril | O35: 32101.96 | S35: abril | T35: =VALUE(O35) -> 32101.96 | AB35: 4 | AC35: 0.90197017 | AE35: Grand Total | AF35: 4697875.6 | AN35: 4 | AO35: 60095.35 | AQ35: 4 | AR35: -572448.01 | AT35: 4 | AU35: -0.9049941
N36: mayo | O36: 62496.85 | S36: mayo | T36: =VALUE(O36) -> 62496.85 | AB36: Grand Total | AC36: -0.066340156 | AQ36: 5 | AR36: -60095.35 | AT36: 5 | AU36: -1
N37: junio | O37: 38599.2 | S37: junio | T37: =VALUE(O37) -> 38599.2
N38: julio | O38: 39152.65 | S38: julio | T38: =VALUE(O38) -> 39152.65
N39: agosto | O39: 53803.08 | S39: agosto | T39: =VALUE(O39) -> 53803.08 | AB39: Row Labels | AC39: Crecimiento Ingresos YoY % | AN39: Row Labels | AO39: Total Gastos | AQ39: Mes | AR39: Gastos
N40: septiembre | O40: 56679.4 | S40: septiembre | T40: =VALUE(O40) -> 56679.4 | AB40: 2025 | AN40: 1 | AO40: 152960.25 | AQ40: =VALUE(AN40) -> 1 | AR40: =VALUE(AO40) -> 152960.25
N41: octubre | O41: 24435.58 | S41: octubre | T41: =VALUE(O41) -> 24435.58 | AB41: 1 | AC41: 2.984643 | AN41: 2 | AO41: 1021955.9 | AQ41: =VALUE(AN41) -> 2 | AR41: =VALUE(AO41) -> 1021955.9
N42: noviembre | O42: 45409.98 | S42: noviembre | T42: =VALUE(O42) -> 45409.98 | AB42: 2 | AC42: 0.022528041 | AN42: 3 | AO42: 730518.46 | AQ42: =VALUE(AN42) -> 3 | AR42: =VALUE(AO42) -> 730518.46
...

Sheet _Estado
B2: _Estado
B5: Importe Pagado
B6: 7278844.7
B8: Importe Pendiente
B9: 1117332.4
B11: Importe Cancelado
B12: 944452.67
B14: Importe Rechazado
B15: 366779.19
B17: Alerta Pendientes
B18: Revisar

Sheet _Rentabilidad
B2: _Rentabilidad
H4: Row Labels | I4: Transacciones
B5: Saldo Neto | H5: Andes Investments SL | I5: 147
B6: -311657.8 | H6: Atlantic Holdings SL | I6: 162
H7: Cresta Partners SA | I7: 171
B8: Margen Neto % | H8: Grupo Meridian SA | I8: 179
B9: -0.066340156 | H9: Iberia Finance SL | I9: 164
H10: Nordic Capital SA | I10: 179
B11: Crecimiento Ingresos YoY % | H11: Grand Total | I11: 1002
B12: 0.20055751
B14: Alerta Rentabilidad | D14: Condition | E14: Color
B15: Revisar | D15: OK | E15: verde
D16: Revisar | E16: rojo

Sheet _Gasto y Control
B2: Gasto y Control
B5: Total Gastos
B6: 5009533.4
B8: Gasto Promedio Mensual
B9: 417461.12
B11: Centro Coste Más Alto
B12: Comercial
B14: Alerta Sobrecoste | D14: Condition | E14: Color
B15: Normal | D15: Normal | E15: verde
D16: Revisar | E16: rojo

Sheet _Cliente-Proveedor
B2: 4_Cliente - Proveedor
B5: Total Ingresos
B6: 4697875.6
B8: Total Gastos
B9: 5009533.4
B11: Clientes Activos
B12: 980
B14: Top 5 Clientes
B15: 0.458279
B17: Top 5 Proveedores
B18: 0.42435369
B22: Importe Cli Año Anterior
B23: 3913078.3
B25: Importe Pro Año Anterior
B26: 3739409.8
B28: Participación Cli x Total
B29: 1
B31: Participación Pro x Total
B32: 1
B34: Var Cli Absoluta YoY
B35: 784797.26
B37: Var Pro Absoluta YoY
B38: 1270123.6

Sheet _KPIs
B2: KPI
B5: Total Ingresos
B6: 4697875.6
B8: Total Gastos
B9: 5009533.4
B11: Saldo Neto
B12: -311657.8
B14: Transacciones
B15: 1002
B17: % ROI
B18: 0.48394743
B20: % Pagadas
B21: 0.6996008
B23: % Margen Bruto
B24: -0.066340156

Sheet _AnalisisTemporal
B2: Analisis Temporal
B5: Crecimiento YoY Bruto
B6: 0.20055751
B8: Crecimiento YoY Neto
B9: -2.7945553
B11: Ingresos Mes Anterior
B14: Crecimiento YoY Promedio
B15: 0.31288986
B17: Mejor Mes
B18: mayo 2024

Sheet dimCalendario
A1: FechaKey | B1: Año | C1: Mes | D1: NombreMes | E1: Trimestre | F1: Día | G1: DiaSemana | H1: FinSemana
A2: 45292 | B2: 2024 | C2: 1 | D2: enero | E2: 1 | F2: 1 | G2: lunes | H2: 0
A3: 45293 | B3: 2024 | C3: 1 | D3: enero | E3: 1 | F3: 2 | G3: martes | H3: 0
A4: 45294 | B4: 2024 | C4: 1 | D4: enero | E4: 1 | F4: 3 | G4: miércoles | H4: 0
A5: 45295 | B5: 2024 | C5: 1 | D5: enero | E5: 1 | F5: 4 | G5: jueves | H5: 0
A6: 45296 | B6: 2024 | C6: 1 | D6: enero | E6: 1 | F6: 5 | G6: viernes | H6: 0
A7: 45297 | B7: 2024 | C7: 1 | D7: enero | E7: 1 | F7: 6 | G7: sábado | H7: 1
A8: 45298 | B8: 2024 | C8: 1 | D8: enero | E8: 1 | F8: 7 | G8: domingo | H8: 1
A9: 45299 | B9: 2024 | C9: 1 | D9: enero | E9: 1 | F9: 8 | G9: lunes | H9: 0
A10: 45300 | B10: 2024 | C10: 1 | D10: enero | E10: 1 | F10: 9 | G10: martes | H10: 0
A11: 45301 | B11: 2024 | C11: 1 | D11: enero | E11: 1 | F11: 10 | G11: miércoles | H11: 0
A12: 45302 | B12: 2024 | C12: 1 | D12: enero | E12: 1 | F12: 11 | G12: jueves | H12: 0
A13: 45303 | B13: 2024 | C13: 1 | D13: enero | E13: 1 | F13: 12 | G13: viernes | H13: 0
... A1097: 46387 | B1097: 2026 | C1097: 12 | D1097: diciembre | E1097: 4 | F1097: 31 | G1097: jueves | H1097: 0

Sheet transacciones_limpias
A1: transaction_id | B1: fecha | C1: anio | D1: mes | E1: nombre_mes | F1: empresa | G1: cliente_proveedor | H1: categoria | I1: subcategoria | J1: tipo_movimiento | K1: importe_limpio | L1: moneda | M1: canal_pago | N1: estado | O1: centro_coste | P1: descripcion | Q1: referencia_externa | R1: pais
A2: TRX-100354 | B2: 45439 | C2: 2024 | D2: 5 | E2: Mayo | F2: Iberia Finance SL | G2: Abad y Aramburu S.L.U. | H2: Marketing | I2: Eventos | J2: Gasto | K2: 6240.86 | L2: EUR | M2: Efectivo | N2: Pagado | O2: Finanzas | P2: Su hombre recuerdo a líder ejemplo hemos sola tipos unidad. | Q2: REF-72287 | R2: Italia
A3: TRX-100032 | B3: 45337 | C3: 2024 | D3: 2 | E3: Febrero | F3: Atlantic Holdings SL | G3: Abad y Mateu S.C.P | H3: Impuestos | I3: Retenciones | J3: Ingreso | K3: 2139.62 | L3: EUR | M3: Bizum | N3: Cancelado | O3: Comercial | P3: Memoria importantes varios arte trabajadores diez cuadro lenguaje estructura. | Q3: REF-67912 | R3: España
A4: TRX-100565 | B4: 46068 | C4: 2026 | D4: 2 | E4: Febrero | F4: Andes Investments SL | G4: Abilio Roldán Azorin S.L.L. | H4: Impuestos | I4: IVA | J4: Gasto | K4: 258294 | L4: EUR | M4: Paypal | N4: Pagado | O4: Dirección | P4: Haya explicó nosotros análisis niño tengo peso juicio. | Q4: REF-45968 | R4: España
A5: TRX-100894 | B5: 45489 | C5: 2024 | D5: 7 | E5: Julio | F5: Cresta Partners SA | G5: Abril Cabello Azcona S.Com. | H5: Logística | I5: Transporte | J5: Ingreso | K5: 4596.41 | L5: GBP | M5: Tarjeta | N5: Pagado | O5: Comercial | P5: Tipo ante hace cuatro gracias. | Q5: REF-87677 | R5: España
A6: TRX-100422 | B6: 45390 | C6: 2024 | D6: 4 | E6: Abril | F6: Andes Investments SL | G6: Acevedo y Villalba S.L. | H6: Financiación | I6: Préstamos | J6: Ingreso | K6: 1780.06 | L6: EUR | M6: Bizum | N6: Pagado | O6: Dirección | P6: Estaban minutos fernando habla mismo ley buen francia libros. | Q6: REF-92511 | R6: Portugal
A7: TRX-100560 | B7: 45499 | C7: 2024 | D7: 7 | E7: Julio | F7: Andes Investments SL | G7: Adalberto Agustí Durán S.Com. | H7: Servicios | I7: Soporte | J7: Ingreso | K7: 2445.39 | L7: EUR | M7: Transferencia | N7: Pagado | O7: TI | P7: Fecha pasar plazo suelo después sin octubre américa boca. | Q7: REF-81237 | R7: Francia
A8: TRX-100831 | B8: 45783 | C8: 2025 | D8: 5 | E8: Mayo | F8: Iberia Finance SL | G8: Adán y Ledesma S.L. | H8: Servicios | I8: Soporte | J8: Gasto | K8: 3779.12 | L8: EUR | M8: Bizum | N8: Rechazado | O8: Operaciones | P8: Producto alguien primero encima varios sabía ésta puso flores esa. | Q8: REF-42394 | R8: España
A9: TRX-100901 | B9: 46052 | C9: 2026 | D9: 1 | E9: Enero | F9: Grupo Meridian SA | G9: Adán y Quintero S.A. | H9: Impuestos | I9: Retenciones | J9: Gasto | K9: 3218.14 | L9: EUR | M9: Bizum | N9: Cancelado | O9: Finanzas | P9: Libro puerto hicieron materia al especie haber vivir. | Q9: REF-63580 | R9: Italia
A10: TRX-100162 | B10: 45638 | C10: 2024 | D10: 12 | E10: Diciembre | F10: Cresta Partners SA | G10: Adelaida Cabello Soria S.L. | H10: Suministros | I10: Energía | J10: Ingreso | K10: 6100.3 | L10: EUR | M10: Bizum | N10: Pagado | O10: Comercial | P10: Posibilidades acción idea cuales países decir hombres comenzó. | Q10: REF-27675 | R10: España
A11: TRX-100721 | B11: 45455 | C11: 2024 | D11: 6 | E11: Junio | F11: Nordic Capital SA | G11: Aguilera y Perera S.L. | H11: Ventas | I11: Venta producto | J11: Gasto | K11: 1335.48 | L11: EUR | M11: Efectivo | N11: Pagado | O11: Comercial | P11: Derecho hacerlo nombre aumento produce especial número busca especial. | Q11: REF-94448 | R11: Francia
A12: TRX-100625 | B12: 45523 | C12: 2024 | D12: 8 | E12: Agosto | F12: Grupo Meridian SA | G12: Ainara Navas Román S.Com. | H12: Servicios | I12: Asesoría | J12: Ingreso | K12: 2582.07 | L12: GBP | M12: Paypal | N12: Pagado | O12: RRHH | P12: Premio vuelta pacientes partes interior vez político proyecto. | Q12: REF-57044 | R12: España
A13: TRX-100045 | B13: 45971 | C13: 2025 | D13: 11 | E13: Noviembre | F13: Iberia Finance SL | G13: Alberola y asociados S.L.L. | H13: Marketing | I13: Contenido | J13: Gasto | K13: 6419.93 | L13: EUR | M13: Tarjeta | N13: Pagado | O13: Comercial | P13: Principio tengo socialista movimiento cómo. | Q13: REF-36100 | R13: España
... A1003: TRX-100718 | B1003: 45497 | C1003: 2024 | D1003: 7 | E1003: Julio | F1003: Grupo Meridian SA | G1003: Zabala y Narváez S.A. | H1003: Ventas | I1003: Suscripción | J1003: Gasto | K1003: 4116.6 | L1003: EUR | M1003: Tarjeta | N1003: Pendiente | O1003: Operaciones | P1003: Etc policía allá sea cultura verdad. | Q1003: REF-67067 | R1003: España

Sheet dimCentroCoste
A1: centro_coste
A2: Dirección
A3: Comercial
A4: Operaciones
A5: Finanzas
A6: TI
A7: RRHH

Sheet dimCategoria
A1: categoria | B1: subcategoria
A2: Consultoría | B2: Finanzas
A3: Consultoría | B3: Operaciones
A4: Consultoría | B4: Estrategia
A5: Financiación | B5: Préstamos
A6: Financiación | B6: Comisiones
A7: Financiación | B7: Intereses
A8: Impuestos | B8: IVA
A9: Impuestos | B9: Retenciones
A10: Impuestos | B10: Sociedades
A11: Logística | B11: Transporte
A12: Logística | B12: Almacenaje
... A31: Ventas | B31: Venta servicio

Sheet dimCliente
A1: empresa | B1: cliente_proveedor | C1: moneda | D1: descripcion | E1: pais
A2: Nordic Capital SA | B2: Banca Privada OLMJ S.L.N.E | C2: EUR | D2: Función sobre sí lado clase. | E2: España
A3: Nordic Capital SA | B3: Soluciones Ibéricos S.Coop. | C3: EUR | D3: Costa a fuego derecha buena tal constitución. | E3: España
A4: Iberia Finance SL | B4: Calatayud & Asociados S.Com. | C4: EUR | D4: Hija españoles cuestión marcha menor teoría interior seguir. | E4: España
A5: Iberia Finance SL | B5: Fernandez & Asociados S.A. | C5: EUR | D5: Lejos hospital ciencia señaló tampoco grupos período. | E5: España
A6: Cresta Partners SA | B6: Promociones Padilla S.A.T. | C6: EUR | D6: Precisamente hechos ese opinión banco centro llegó. | E6: España
A7: Iberia Finance SL | B7: Hotel Morata & Asociados S.A.T. | C7: EUR | D7: Puerto estoy uno humana sol. | E7: España
A8: Andes Investments SL | B8: Garcia y asociados S.Com. | C8: EUR | D8: Otras madrid entrada resultado sean empresas b tengo somos. | E8: España
A9: Iberia Finance SL | B9: Transportes Bou S.L. | C9: EUR | D9: Cómo medio análisis especialmente buen. | E9: España
A10: Cresta Partners SA | B10: Benigna Iglesias Alberdi S.L. | C10: EUR | D10: Acto quiero público república estaba. | E10: España
A11: Andes Investments SL | B11: Cruz y Santiago S.A. | C11: EUR | D11: R fecha universidad forma hubo consumo universidad. | E11: España
A12: Cresta Partners SA | B12: Despacho del Levante S.L. | C12: EUR | D12: Jamás material grado favor valor estaba dios hospital fuego estar. | E12: España
... A981: Cresta Partners SA | B981: Finanzas SN S.A.T. | C981: EUR | D981: Opinión superior elecciones sociales maría actual suerte campaña. | E981: España

Sheet TB_CanalPago
A1: Index | B1: canal_pago
A2: 0 | B2: Bizum
A3: 1 | B3: SEPA
A4: 2 | B4: Tarjeta
A5: 3 | B5: Efectivo
A6: 4 | B6: Paypal
A7: 5 | B7: Transferencia

Sheet TB_Estado
A1: Index | B1: estado
A2: 0 | B2: Pagado
A3: 1 | B3: Pendiente
A4: 2 | B4: Cancelado
A5: 3 | B5: Rechazado
